Workbook

Sheet Cover Page
B1: APOLLO ENERGY RESOURCES
B2: Pro Forma Financial Model · Confidential · March 2026
B6: KEY MODEL OUTPUTS
B8: ="Exit Equity Value ("&TEXT(Assumptions!G165,"0.0")&"x)" -> Exit Equity Value (5.0x) | C8: DCF Cross-Check | D8: ="Equity MOIC (5-Yr, "&TEXT(Assumptions!G165,"0.0")&"x)" -> Equity MOIC (5-Yr, 5.0x) | E8: Active Scenario
B9: =TEXT('DCF & Returns'!J73,"$#,##0\K") -> $23,406K | C9: =TEXT('DCF & Returns'!B28,"$#,##0\K") -> $16,198K | D9: =TEXT('DCF & Returns'!J84,"0.0\×") -> 15.9× | E9: ='Control Panel'!C7 -> Base
B10: ="WACC "&TEXT(Assumptions!B11,"0.0%")&" · TGR "&TEXT(Assumptions!B12,"0.0%")&" · Active scenario: "&'Control Panel'!C7 -> WACC 11.1% · TGR 2.5% · Active scenario: Base | C10: ="$"&TEXT('DCF & Returns'!B50,"#,##0")&"K equity invested · "&TEXT(Assumptions!G165,"0.0")&"× exit multiple (5-yr)" -> $1,500K equity invested · 5.0× exit multiple (5-yr) | D10: ="Exit multiple: "&TEXT(Assumptions!B165,"0.0")&"× · "&TEXT(Assumptions!B157*100,"0")&"% probability weight" -> Exit multiple: 3.0× · 15% probability weight | E10: ="Exit multiple: "&TEXT(Assumptions!F165,"0.0")&"× · "&TEXT(Assumptions!F157*100,"0")&"% probability weight" -> Exit multiple: 7.5× · 10% probability weight
B11: DCF Enterprise Value | C11: 5-Year MOIC | D11: Exit Equity (Hyper Bear) | E11: Exit Equity (Hyper Bull)
B12: ='DCF & Returns'!B24 -> 18169.2 | C12: ='DCF & Returns'!J84 -> 15.918845 | D12: =Assumptions!B165*'DCF & Returns'!J64-'DCF & Returns'!J65 -> 14733.412 | E12: =Assumptions!F165*'DCF & Returns'!J64-'DCF & Returns'!J65 -> 34245.744
B14: MODEL STRUCTURE
B16: Sheet | C16: Function | D16: Key Output | E16: Status | F16: Color
B17: Assumptions | C17: Inputs, growth rates, margins, scenarios | D17: Scenario toggle (Bull/Base/Bear) | E17: ✓ | F17: ●
B19: Control Panel | C19: 5-scenario × 5-credit-tier toggle interface | D19: Master scenario & credit dropdowns | E19: ✓ | F19: ●
B21: Revenue Build | C21: Monthly revenue by division (5 divs) | D21: ="FY2026E: $"&TEXT('Income Statement'!N3,"#,##0")&"K → FY2030E: $"&TEXT('Income Statement'!R3,"#,##0")&"K" -> FY2026E: $8,365K → FY2030E: $16,689K | E21: ✓ | F21: ●
B22: Income Statement | C22: Monthly → annual consolidated P&L | D22: ="FY2030E NI: $"&TEXT('Income Statement'!R27,"#,##0")&"K" -> FY2030E NI: $1,971K | E22: ✓ | F22: ●
B23: Balance Sheet | C23: Annual balance sheet (FY2026–FY2030) | D23: ="Total assets: $"&TEXT('Balance Sheet'!N26,"#,##0")&"K → $"&TEXT('Balance Sheet'!R26,"#,##0")&"K" -> Total assets: $7,365K → $8,067K | E23: ✓ | F23: ●
B24: Cash Flow | C24: Monthly cash flow statement | D24: Monthly NI sums to annual CF | E24: ✓ | F24: ●
B28: Debt Schedule | C28: Amortization, covenants, monthly detail | D28: ="Total debt: $"&TEXT('Debt Schedule'!N68,"#,##0")&"K → $"&TEXT('Debt Schedule'!R68,"#,##0")&"K (FY2030)" -> Total debt: $4,602K → $477K (FY2030) | E28: ✓ | F28: ●
B30: DCF & Returns | C30: DCF with sensitivity table | D30: ="EV: $"&TEXT('DCF & Returns'!B24,"#,##0")&"K · Equity: $"&TEXT('DCF & Returns'!B28,"#,##0")&"K (cross-ref)" -> EV: $18,169K · Equity: $16,198K (cross-ref) | E30: ✓ | F30: ●
B34: KEY ASSUMPTIONS
B36: Forecast horizon | C36: 5 years (FY2026E – FY2030E) | D36: Entity structure | E36: Pass-through LLC (31% tax rate)
B37: Year 1 granularity | C37: Monthly | D37: Exit multiple | E37: =TEXT(Assumptions!G165,"0.0")&"x EV/EBITDA (scenario-dependent)" -> 5.0x EV/EBITDA (scenario-dependent)
B38: WACC | C38: =Assumptions!B11 -> 0.11147818 | D38: Equity investment | E38: ="$"&TEXT(Assumptions!B79,"#,##0")&"K ("&TEXT(Assumptions!B79/Assumptions!B81,"0%")&" of $"&TEXT(Assumptions!B81,"#,##0")&"K total)" -> $1,500K (50% of $3,000K total)
B39: Terminal growth rate | C39: =Assumptions!B12 -> 0.025 | D39: Total capital injection | E39: ="$"&TEXT(Assumptions!B81,"#,##0")&"K (debt + equity)" -> $3,000K (debt + equity)
B40: Revenue CAGR (5-yr) | C40: =('Income Statement'!R3/'Income Statement'!N3)^(1/5)-1 -> 0.14812617 | D40: Depreciation | E40: 5-year straight-line
B41: FY2025A revenue | C41: $4,916K (Apollo actual, excl. Installations acq.) | D41: Scenario toggle | E41: ='Control Panel'!C7&" (Control Panel!C7)" -> Base (Control Panel!C7)
B42: FY2030E revenue | C42: =TEXT('Income Statement'!R3,"$#,##0")&"K" -> $16,689K | D42: Installations acquisition | E42: FY2026 (Month 16 base timing)
B43: Blended GM (FY2030) | C43: ='Income Statement'!R30/'Income Statement'!R3 -> 0.2598167 | D43: Covenant max Debt/EBITDA | E43: =TEXT(Assumptions!B98,"0.0")&"×" -> 5.5×
B47: COLOR CODING CONVENTIONS
B49: Blue text | C49: Hardcoded inputs — values the user can change for scenario analysis
B50: Black text | C50: Formulas and calculations — do not overwrite
B51: Yellow highlight | C51: Key assumptions that need attention or verification
B52: Green text | C52: Cross-sheet links pulling from other worksheets
B56: SHEET TAB COLORS BY FUNCTION
B58: ● | C58: Dark Navy | D58: Navigation & Controls | E58: Cover Page, Assumptions, Control Panel
B59: ● | C59: Gray | D59: Actuals (locked)
B60: ● | C60: Green | D60: Core Financial Statements | E60: Revenue Build, IS, BS, CF
B61: ● | C61: Red | D61: Risk & Stress Testing
B62: ● | C62: Orange | D62: Debt & Credit | E62: Debt Schedule
B63: ● | C63: Purple | D63: Valuation & Returns | E63: DCF & Returns
B67: CRITICAL NOTES
...

Sheet Assumptions
A1: APOLLO ENERGY RESOURCES — KEY ASSUMPTIONS
A3: GENERAL ASSUMPTIONS
A4: Model Start Date | B4: 46023
A5: Forecast Horizon (Years) | B5: 5
A6: Year 1 Granularity | B6: Monthly
A7: Currency | B7: USD ($)
A8: Units | B8: Thousands ($000s)
D9: Installations = acquisition ($1.8M trailing rev). FY2026 = first year under Apollo ownership.
A11: WACC | B11: =IF($B$205="Convergence",B219,0.12) -> 0.11147818
A12: Terminal Growth Rate | B12: =G159 -> 0.025
A13: Effective Tax Rate (Pass-Through) | B13: 0.31
A15: Blended Net Margin Target (5-Yr) | B15: 0.22
A16: Blended Revenue Growth (Avg) | B16: 0.22
A17: CAPEX as % of Revenue Growth | B17: =G161 -> 0.4
A18: Back-Office Efficiency Discount | B18: 0
A19: Depreciation — Useful Life (Years) | B19: 5
A20: Note: FY2026E-FY2030E revenue inputs below are base figures only. Revenue Build applies the selected scenario multiplier and winter/seasonality uplift, so reported revenue can be higher than these base inputs.
A21: REVENUE ASSUMPTIONS BY DIVISION
A22: Revenue ($000s) | B22: 2025A PF | C22: 2026E | D22: 2027E | E22: 2028E | F22: 2029E | G22: 2030E | H22: 5-Yr CAGR
A23: Logistics | B23: 3735 | C23: 4810 | D23: 5291 | E23: 5768 | F23: 6287 | G23: 6859 | H23: =(G23/B23)^(1/5)-1 -> 0.12926025
A24: Field Services | B24: 231 | C24: 623 | D24: 872 | E24: 1134 | F24: 1418 | G24: 1702 | H24: =(G24/B24)^(1/5)-1 -> 0.49097209
A25: Installations | B25: 1800 | C25: 1400 | D25: 2203 | E25: 3304 | F25: 4626 | G25: 5782 | H25: $1.4M FY2026 baseline. Growth trajectory maintained. Target: 18% div net margin FY2026, +5bps/yr improvement (goal).
A26: Apollo Fleet Services | B26: 46 | C26: 111 | D26: 167 | E26: 234 | F26: 304 | G26: 380 | H26: =(G26/B26)^(1/5)-1 -> 0.5254752
A27: Apollo Power Management | B27: 0 | C27: 177 | D27: 230 | E27: 299 | F27: 359 | G27: 413 | H27: =(G27/C27)^(1/4)-1 -> 0.23593092
A29: Total Revenue | B29: =SUM(B23:B27) -> 5812 | C29: ='Revenue Build'!N10 -> 8365.3 | D29: ='Revenue Build'!O10 -> 10079.48 | E29: ='Revenue Build'!P10 -> 12130.851 | F29: ='Revenue Build'!Q10 -> 14465.389 | G29: ='Revenue Build'!R10 -> 16688.973 | H29: =(G29/B29)^(1/5)-1 -> 0.23486875
A30: YoY Revenue Growth | C30: =C29/B29-1 -> 0.43931521 | D30: =D29/C29-1 -> 0.20491554 | E30: =E29/D29-1 -> 0.20351955 | F30: =F29/E29-1 -> 0.19244635 | G30: =G29/F29-1 -> 0.15371751
A31: Brokerage Gross Margin | B31: 0.15 | C31: Pass-through margin on ~$1,182K brokerage revenue
A32: Brokerage Base Revenue ($K) | B32: 1182
A34: Brokerage Annual Growth Rate | B34: 0.04
A35: Other Current Assets (% of Revenue) | B35: ='Balance Sheet'!B9/B29 -> 0.0070543703
A36: GROSS MARGIN ASSUMPTIONS BY DIVISION
A37: Gross Margin % | B37: 2025A PF | C37: 2026E | D37: 2027E | E37: 2028E | F37: 2029E | G37: 2030E | H37: Notes
A38: Logistics | B38: 0.25 | C38: 0.22 | D38: =C38+0.02*$G$223 -> 0.24 | E38: =C38+0.03*$G$223 -> 0.25 | F38: =C38+0.04*$G$223 -> 0.26 | G38: =C38+0.05*$G$223 -> 0.27 | H38: Insurance-heavy; marginal improvement only
A39: Field Services | B39: 0.45 | C39: 0.38 | D39: =C39-0.01*$G$223 -> 0.37 | E39: =C39-0.01*$G$223 -> 0.37 | F39: =C39 -> 0.38 | G39: =C39+0.01*$G$223 -> 0.39 | H39: Ramp from 38% to target +700bps over 5yr; management targets above industry.
A40: Installations | B40: 0.38 | C40: 0.45 | D40: =C40 -> 0.45 | E40: =C40+0.01*$G$223 -> 0.46 | F40: =C40+0.01*$G$223 -> 0.46 | G40: =C40+0.02*$G$223 -> 0.47 | H40: 45% GM per mgmt (electrical contractors avg 40-50%)
A41: Apollo Fleet Services | B41: 0.3 | C41: 0.25 | D41: =C41+0.02*$G$223 -> 0.27 | E41: =C41+0.03*$G$223 -> 0.28 | F41: =C41+0.04*$G$223 -> 0.29 | G41: =C41+0.05*$G$223 -> 0.3 | H41: Equipment maintenance 25-30% GM range; steady improvement via utilization
A42: Apollo Power Management | C42: 0.25 | D42: =C42+0.02*$G$223 -> 0.27 | E42: =C42+0.04*$G$223 -> 0.29 | F42: =C42+0.05*$G$223 -> 0.3 | G42: =C42+0.06*$G$223 -> 0.31 | H42: 25% blended start per mgmt (compliance infra already in place)
A43: Blended Gross Margin | B43: =SUMPRODUCT(B23:B27,B38:B42)/B29 -> 0.29860633 | C43: =SUMPRODUCT(C23:C27,C38:C42)/C29 -> 0.23871708 | D43: =SUMPRODUCT(D23:D27,D38:D42)/D29 -> 0.26698004 | E43: =SUMPRODUCT(E23:E27,E38:E42)/E29 -> 0.29129448 | F43: =SUMPRODUCT(F23:F27,F38:F42)/F29 -> 0.31089934 | G43: =SUMPRODUCT(G23:G27,G38:G42)/G29 -> 0.32807771
A45: OPERATING EXPENSE ASSUMPTIONS
A46: Operating Expenses ($000s) | B46: 2025A | C46: 2026E | D46: 2027E | E46: 2028E | F46: 2029E | G46: 2030E | H46: Notes
...

Sheet Control Panel
B2: APOLLO ENERGY RESOURCES
B3: Control Panel — Scenario & Credit Controls
B5: SCENARIO & CREDIT CONTROLS
B7: Active Scenario | C7: Base | E7: ◀ Click to select scenario
B8: Active Credit Tier | C8: Tier 2 | E8: ◀ Click to select credit tier
B11: SCENARIO PARAMETERS
B12: Parameter | C12: Active | E12: Hyper Bear | F12: Bear | G12: Base | H12: Bull | I12: Hyper Bull
B13: Rev Multiplier — Logistics | C13: =Assumptions!G170 -> 1 | E13: =Assumptions!B170 -> 0.75 | F13: =Assumptions!C170 -> 0.88 | G13: =Assumptions!D170 -> 1 | H13: =Assumptions!E170 -> 1.08 | I13: =Assumptions!F170 -> 1.15
B14: Rev Multiplier — Field Services | C14: =Assumptions!G171 -> 1 | E14: =Assumptions!B171 -> 0.35 | F14: =Assumptions!C171 -> 0.62 | G14: =Assumptions!D171 -> 1 | H14: =Assumptions!E171 -> 1.2 | I14: =Assumptions!F171 -> 1.45
B15: Rev Multiplier — Installations | C15: =Assumptions!G174 -> 1 | E15: =Assumptions!B174 -> 0.82 | F15: =Assumptions!C174 -> 0.91 | G15: =Assumptions!D174 -> 1 | H15: =Assumptions!E174 -> 1.12 | I15: =Assumptions!F174 -> 1.22
B16: Rev Multiplier — Fleet Services | C16: =Assumptions!G172 -> 1 | E16: =Assumptions!B172 -> 0.9 | F16: =Assumptions!C172 -> 0.95 | G16: =Assumptions!D172 -> 1 | H16: =Assumptions!E172 -> 1.04 | I16: =Assumptions!F172 -> 1.07
B17: Rev Multiplier — Power Mgmt | C17: =Assumptions!G173 -> 1 | E17: =Assumptions!B173 -> 0.8 | F17: =Assumptions!C173 -> 0.9 | G17: =Assumptions!D173 -> 1 | H17: =Assumptions!E173 -> 1.1 | I17: =Assumptions!F173 -> 1.18
B18: GM Delta — Avg (ppt) | C18: =AVERAGE(Assumptions!G177:G181) -> 0 | E18: =AVERAGE(Assumptions!B177:B181) -> -0.098 | F18: =AVERAGE(Assumptions!C177:C181) -> -0.051 | G18: =AVERAGE(Assumptions!D177:D181) -> 0 | H18: =AVERAGE(Assumptions!E177:E181) -> 0.024 | I18: =AVERAGE(Assumptions!F177:F181) -> 0.041
B19: Insurance Multiplier | C19: =Assumptions!G158 -> 1 | E19: =Assumptions!B158 -> 1.25 | F19: =Assumptions!C158 -> 1.12 | G19: =Assumptions!D158 -> 1 | H19: =Assumptions!E158 -> 1.02 | I19: =Assumptions!F158 -> 1.1
B20: CAPEX Reinvestment % | C20: =Assumptions!G161 -> 0.4 | E20: =Assumptions!B161 -> 0.15 | F20: =Assumptions!C161 -> 0.25 | G20: =Assumptions!D161 -> 0.4 | H20: =Assumptions!E161 -> 0.5 | I20: =Assumptions!F161 -> 0.55
B21: Terminal Growth Rate | C21: =Assumptions!G159 -> 0.025 | E21: =Assumptions!B159 -> 0.005 | F21: =Assumptions!C159 -> 0.015 | G21: =Assumptions!D159 -> 0.025 | H21: =Assumptions!E159 -> 0.025 | I21: =Assumptions!F159 -> 0.025
B22: WACC Scenario Adj | C22: =Assumptions!G160 -> 0 | E22: =Assumptions!B160 -> 0.025 | F22: =Assumptions!C160 -> 0.0125 | G22: =Assumptions!D160 -> 0 | H22: =Assumptions!E160 -> -0.005 | I22: =Assumptions!F160 -> -0.01
B23: Exit Multiple (EV/EBITDA) | C23: =Assumptions!G165 -> 5 | E23: =Assumptions!B165 -> 3 | F23: =Assumptions!C165 -> 4 | G23: =Assumptions!D165 -> 5 | H23: =Assumptions!E165 -> 6 | I23: =Assumptions!F165 -> 7.5
B24: Working Capital Days (net) | C24: =Assumptions!G167 -> 30 | E24: =Assumptions!B167 -> 50 | F24: =Assumptions!C167 -> 38 | G24: =Assumptions!D167 -> 30 | H24: =Assumptions!E167 -> 28 | I24: =Assumptions!F167 -> 25
B25: Probability Weights | C25: =Assumptions!G157 -> 1 | E25: =Assumptions!B157 -> 0.15 | F25: =Assumptions!C157 -> 0.25 | G25: =Assumptions!D157 -> 0.35 | H25: =Assumptions!E157 -> 0.15 | I25: =Assumptions!F157 -> 0.1
B26: EXTENDED SCENARIO PARAMETERS
B27: GM Ramp Pace | C27: =Assumptions!G223 -> 1 | E27: =Assumptions!B223 -> 0 | F27: =Assumptions!C223 -> 0.5 | G27: =Assumptions!D223 -> 1 | H27: =Assumptions!E223 -> 1.3 | I27: =Assumptions!F223 -> 1.5
B28: G&A Multiplier | C28: =Assumptions!G224 -> 1 | E28: =Assumptions!B224 -> 1.15 | F28: =Assumptions!C224 -> 1.08 | G28: =Assumptions!D224 -> 1 | H28: =Assumptions!E224 -> 0.97 | I28: =Assumptions!F224 -> 0.95
B29: S&M Multiplier | C29: =Assumptions!G225 -> 1 | E29: =Assumptions!B225 -> 0.7 | F29: =Assumptions!C225 -> 0.85 | G29: =Assumptions!D225 -> 1 | H29: =Assumptions!E225 -> 1.15 | I29: =Assumptions!F225 -> 1.3
B30: IT Multiplier | C30: =Assumptions!G226 -> 1 | E30: =Assumptions!B226 -> 1.1 | F30: =Assumptions!C226 -> 1.05 | G30: =Assumptions!D226 -> 1 | H30: =Assumptions!E226 -> 1 | I30: =Assumptions!F226 -> 0.95
B31: Rev Trajectory Drift | C31: =Assumptions!G227 -> 0 | E31: =Assumptions!B227 -> -0.03 | F31: =Assumptions!C227 -> -0.015 | G31: =Assumptions!D227 -> 0 | H31: =Assumptions!E227 -> 0.03 | I31: =Assumptions!F227 -> 0.05
B32: DSO Adjustment (days) | C32: =Assumptions!G228 -> 0 | E32: =Assumptions!B228 -> 8 | F32: =Assumptions!C228 -> 4 | G32: =Assumptions!D228 -> 0 | H32: =Assumptions!E228 -> -2 | I32: =Assumptions!F228 -> -3
B33: Insurance Base Factor | C33: =Assumptions!G229 -> 1 | E33: =Assumptions!B229 -> 1.1 | F33: =Assumptions!C229 -> 1.05 | G33: =Assumptions!D229 -> 1 | H33: =Assumptions!E229 -> 0.98 | I33: =Assumptions!F229 -> 0.95
B34: Maintenance CAPEX % | C34: =Assumptions!G230 -> 0.015 | E34: =Assumptions!B230 -> 0.012 | F34: =Assumptions!C230 -> 0.013 | G34: =Assumptions!D230 -> 0.015 | H34: =Assumptions!E230 -> 0.017 | I34: =Assumptions!F230 -> 0.018
B36: ACTIVE CREDIT FACILITY | E36: KEY MODEL OUTPUTS
B37: Parameter | C37: Active Value | E37: Metric | F37: FY2026E | G37: FY2027E | H37: FY2028E | I37: FY2029E
B38: Commitment ($K) | C38: =Assumptions!G187 -> 1000 | E38: Revenue ($K) | F38: ='Income Statement'!N3 -> 8365.3 | G38: ='Income Statement'!O3 -> 10079.48 | H38: ='Income Statement'!P3 -> 12130.851 | I38: ='Income Statement'!Q3 -> 14465.389
B39: Interest Rate | C39: =Assumptions!G188 -> 0.06 | E39: Gross Margin % | F39: ='Income Statement'!N6 -> 0.26257095 | G39: ='Income Statement'!O6 -> 0.2884748 | H39: ='Income Statement'!P6 -> 0.31056153 | I39: ='Income Statement'!Q6 -> 0.32841165
B40: Commitment Fee | C40: =Assumptions!G189 -> 0.006 | E40: EBITDA ($K) | F40: ='Income Statement'!N30 -> 1152.4848 | G40: ='Income Statement'!O30 -> 1800.676 | H40: ='Income Statement'!P30 -> 2565.3757 | I40: ='Income Statement'!Q30 -> 3442.6024
B41: Draw Schedule (%) | C41: =Assumptions!G191 -> 0.6 | E41: Net Income ($K) | F41: ='Income Statement'!N27 -> 235.44245 | G41: ='Income Statement'!O27 -> 524.42731 | H41: ='Income Statement'!P27 -> 978.49323 | I41: ='Income Statement'!Q27 -> 1469.5411
B42: Term (Months) | C42: =Assumptions!G192 -> 48 | E42: Free Cash Flow ($K) | F42: ='Cash Flow'!N15+'Cash Flow'!N22 -> -1277.5575 | G42: ='Cash Flow'!O15+'Cash Flow'!O22 -> 75.427307 | H42: ='Cash Flow'!P15+'Cash Flow'!P22 -> 744.49323 | I42: ='Cash Flow'!Q15+'Cash Flow'!Q22 -> 1304.5411
E43: Total Debt ($K) | F43: ='Debt Schedule'!N68 -> 4602.3639 | G43: ='Debt Schedule'!O68 -> 2967.6003 | H43: ='Debt Schedule'!P68 -> 2123.0706 | I43: ='Debt Schedule'!Q68 -> 1330.7032
B44: VALUATION SUMMARY
B45: Metric | C45: Value | E45: MODEL INTEGRITY CHECKS
B46: WACC | C46: =Assumptions!B11 -> 0.11147818 | E46: Check | G46: Status
...

Sheet Revenue Build
A1: APOLLO ENERGY RESOURCES — REVENUE BUILD
B2: 46048 | C2: 46079 | D2: 46107 | E2: 46138 | F2: 46168 | G2: 46199 | H2: 46229 | I2: 46260 | J2: 46291 | K2: 46321 | L2: 46352 | M2: 46382 | N2: FY2026 | O2: FY2027 | P2: FY2028 | Q2: FY2029 | R2: FY2030
A3: REVENUE BY DIVISION ($000s)
A4: Logistics | B4: =Assumptions!C23*Assumptions!B108*Assumptions!$G$170*(1-Assumptions!$G$162) -> 312.65 | C4: =Assumptions!C23*Assumptions!C108*Assumptions!$G$170*(1-Assumptions!$G$162) -> 312.65 | D4: =Assumptions!C23*Assumptions!D108*Assumptions!$G$170*(1-Assumptions!$G$162) -> 360.75 | E4: =Assumptions!C23*Assumptions!E108*Assumptions!$G$170*(1-Assumptions!$G$162) -> 408.85 | F4: =Assumptions!C23*Assumptions!F108*Assumptions!$G$170*(1-Assumptions!$G$162) -> 456.95 | G4: =Assumptions!C23*Assumptions!G108*Assumptions!$G$170*(1-Assumptions!$G$162) -> 481 | H4: =Assumptions!C23*Assumptions!H108*Assumptions!$G$170*(1-Assumptions!$G$162) -> 505.05 | I4: =Assumptions!C23*Assumptions!J108*Assumptions!$G$170*(1-Assumptions!$G$162) -> 505.05 | J4: =Assumptions!C23*Assumptions!K108*Assumptions!$G$170*(1-Assumptions!$G$162) -> 456.95 | K4: =Assumptions!C23*Assumptions!L108*Assumptions!$G$170*(1-Assumptions!$G$162) -> 384.8 | L4: =Assumptions!C23*Assumptions!M108*Assumptions!$G$170*(1-Assumptions!$G$162) -> 312.65 | M4: =Assumptions!C23*Assumptions!N108*Assumptions!$G$170*(1-Assumptions!$G$162) -> 312.65 | N4: =SUM(B4:M4) -> 4810 | O4: =Assumptions!D23*Assumptions!$G$170*(1+Assumptions!$G$227)^1*(1-Assumptions!$G$162) -> 5291 | P4: =Assumptions!E23*Assumptions!$G$170*(1+Assumptions!$G$227)^2*(1-Assumptions!$G$162) -> 5768 | Q4: =Assumptions!F23*Assumptions!$G$170*(1+Assumptions!$G$227)^3*(1-Assumptions!$G$162) -> 6287 | R4: =Assumptions!G23*Assumptions!$G$170*(1+Assumptions!$G$227)^4*(1-Assumptions!$G$162) -> 6859
A5: Field Services | B5: =Assumptions!C24*Assumptions!B109*Assumptions!$G$171*(1+Assumptions!$G$164*Assumptions!$G$163/5) -> 41.118 | C5: =Assumptions!C24*Assumptions!C109*Assumptions!$G$171*(1+Assumptions!$G$164*Assumptions!$G$163/5) -> 41.118 | D5: =Assumptions!C24*Assumptions!D109*Assumptions!$G$171*(1+Assumptions!$G$164*Assumptions!$G$163/5) -> 47.971 | E5: =Assumptions!C24*Assumptions!E109*Assumptions!$G$171*(1+Assumptions!$G$164*Assumptions!$G$163/5) -> 58.2505 | F5: =Assumptions!C24*Assumptions!F109*Assumptions!$G$171*(1+Assumptions!$G$164*Assumptions!$G$163/5) -> 68.53 | G5: =Assumptions!C24*Assumptions!G109*Assumptions!$G$171*(1+Assumptions!$G$164*Assumptions!$G$163/5) -> 75.383 | H5: =Assumptions!C24*Assumptions!H109*Assumptions!$G$171*(1+Assumptions!$G$164*Assumptions!$G$163/5) -> 78.8095 | I5: =Assumptions!C24*Assumptions!J109*Assumptions!$G$171*(1+Assumptions!$G$164*Assumptions!$G$163/5) -> 75.383 | J5: =Assumptions!C24*Assumptions!K109*Assumptions!$G$171*(1+Assumptions!$G$164*Assumptions!$G$163/5) -> 65.1035 | K5: =Assumptions!C24*Assumptions!L109*Assumptions!$G$171*(1+Assumptions!$G$164*Assumptions!$G$163/5) -> 51.3975 | L5: =Assumptions!C24*Assumptions!M109*Assumptions!$G$171*(1+Assumptions!$G$164*Assumptions!$G$163/5) -> 44.5445 | M5: =Assumptions!C24*Assumptions!N109*Assumptions!$G$171*(1+Assumptions!$G$164*Assumptions!$G$163/5) -> 37.6915 | N5: =SUM(B5:M5) -> 685.3 | O5: =Assumptions!D24*Assumptions!$G$171*(1+Assumptions!$G$227)^1*(1+Assumptions!$G$164*Assumptions!$G$163/5) -> 959.2 | P5: =Assumptions!E24*Assumptions!$G$171*(1+Assumptions!$G$227)^2*(1+Assumptions!$G$164*Assumptions!$G$163/5) -> 1247.4 | Q5: =Assumptions!F24*Assumptions!$G$171*(1+Assumptions!$G$227)^3*(1+Assumptions!$G$164*Assumptions!$G$163/5) -> 1559.8 | R5: =Assumptions!G24*Assumptions!$G$171*(1+Assumptions!$G$227)^4*(1+Assumptions!$G$164*Assumptions!$G$163/5) -> 1872.2
A6: Installations | B6: =Assumptions!C25*Assumptions!B110*Assumptions!$G$174 -> 77 | C6: =Assumptions!C25*Assumptions!C110*Assumptions!$G$174 -> 84 | D6: =Assumptions!C25*Assumptions!D110*Assumptions!$G$174 -> 105 | E6: =Assumptions!C25*Assumptions!E110*Assumptions!$G$174 -> 126 | F6: =Assumptions!C25*Assumptions!F110*Assumptions!$G$174 -> 147 | G6: =Assumptions!C25*Assumptions!G110*Assumptions!$G$174 -> 161 | H6: =Assumptions!C25*Assumptions!H110*Assumptions!$G$174 -> 168 | I6: =Assumptions!C25*Assumptions!J110*Assumptions!$G$174 -> 161 | J6: =Assumptions!C25*Assumptions!K110*Assumptions!$G$174 -> 133 | K6: =Assumptions!C25*Assumptions!L110*Assumptions!$G$174 -> 105 | L6: =Assumptions!C25*Assumptions!M110*Assumptions!$G$174 -> 70 | M6: =Assumptions!C25*Assumptions!N110*Assumptions!$G$174 -> 63 | N6: =SUM(B6:M6) -> 1400 | O6: =Assumptions!D25*Assumptions!$G$174*(1+Assumptions!$G$227)^1 -> 2203 | P6: =Assumptions!E25*Assumptions!$G$174*(1+Assumptions!$G$227)^2 -> 3304 | Q6: =Assumptions!F25*Assumptions!$G$174*(1+Assumptions!$G$227)^3 -> 4626 | R6: =Assumptions!G25*Assumptions!$G$174*(1+Assumptions!$G$227)^4 -> 5782
A7: Apollo Fleet Services | B7: =Assumptions!C26*Assumptions!B111*Assumptions!$G$172 -> 8.325 | C7: =Assumptions!C26*Assumptions!C111*Assumptions!$G$172 -> 8.325 | D7: =Assumptions!C26*Assumptions!D111*Assumptions!$G$172 -> 8.88 | E7: =Assumptions!C26*Assumptions!E111*Assumptions!$G$172 -> 9.435 | F7: =Assumptions!C26*Assumptions!F111*Assumptions!$G$172 -> 9.99 | G7: =Assumptions!C26*Assumptions!G111*Assumptions!$G$172 -> 10.545 | H7: =Assumptions!C26*Assumptions!H111*Assumptions!$G$172 -> 10.545 | I7: =Assumptions!C26*Assumptions!J111*Assumptions!$G$172 -> 9.99 | J7: =Assumptions!C26*Assumptions!K111*Assumptions!$G$172 -> 9.435 | K7: =Assumptions!C26*Assumptions!L111*Assumptions!$G$172 -> 8.88 | L7: =Assumptions!C26*Assumptions!M111*Assumptions!$G$172 -> 8.325 | M7: =Assumptions!C26*Assumptions!N111*Assumptions!$G$172 -> 8.325 | N7: =SUM(B7:M7) -> 111 | O7: =Assumptions!D26*Assumptions!$G$172*(1+Assumptions!$G$227)^1 -> 167 | P7: =Assumptions!E26*Assumptions!$G$172*(1+Assumptions!$G$227)^2 -> 234 | Q7: =Assumptions!F26*Assumptions!$G$172*(1+Assumptions!$G$227)^3 -> 304 | R7: =Assumptions!G26*Assumptions!$G$172*(1+Assumptions!$G$227)^4 -> 380
A8: Apollo Power Management | B8: =Assumptions!C27*Assumptions!B112*Assumptions!$G$173 -> 7.08 | C8: =Assumptions!C27*Assumptions!C112*Assumptions!$G$173 -> 7.965 | D8: =Assumptions!C27*Assumptions!D112*Assumptions!$G$173 -> 10.62 | E8: =Assumptions!C27*Assumptions!E112*Assumptions!$G$173 -> 14.16 | F8: =Assumptions!C27*Assumptions!F112*Assumptions!$G$173 -> 17.7 | G8: =Assumptions!C27*Assumptions!G112*Assumptions!$G$173 -> 23.01 | H8: =Assumptions!C27*Assumptions!H112*Assumptions!$G$173 -> 24.78 | I8: =Assumptions!C27*Assumptions!J112*Assumptions!$G$173 -> 23.01 | J8: =Assumptions!C27*Assumptions!K112*Assumptions!$G$173 -> 17.7 | K8: =Assumptions!C27*Assumptions!L112*Assumptions!$G$173 -> 13.275 | L8: =Assumptions!C27*Assumptions!M112*Assumptions!$G$173 -> 9.735 | M8: =Assumptions!C27*Assumptions!N112*Assumptions!$G$173 -> 7.965 | N8: =SUM(B8:M8) -> 177 | O8: =Assumptions!D27*Assumptions!$G$173*(1+Assumptions!$G$227)^1 -> 230 | P8: =Assumptions!E27*Assumptions!$G$173*(1+Assumptions!$G$227)^2 -> 299 | Q8: =Assumptions!F27*Assumptions!$G$173*(1+Assumptions!$G$227)^3 -> 359 | R8: =Assumptions!G27*Assumptions!$G$173*(1+Assumptions!$G$227)^4 -> 413
A9: Brokerage | B9: =Assumptions!$B$32/12 -> 98.5 | C9: =Assumptions!$B$32/12 -> 98.5 | D9: =Assumptions!$B$32/12 -> 98.5 | E9: =Assumptions!$B$32/12 -> 98.5 | F9: =Assumptions!$B$32/12 -> 98.5 | G9: =Assumptions!$B$32/12 -> 98.5 | H9: =Assumptions!$B$32/12 -> 98.5 | I9: =Assumptions!$B$32/12 -> 98.5 | ... M9: =Assumptions!$B$32/12 -> 98.5 | N9: =SUM(B9:M9) -> 1182 | O9: =N9*(1+Assumptions!$B$34) -> 1229.28 | P9: =O9*(1+Assumptions!$B$34) -> 1278.4512 | Q9: =P9*(1+Assumptions!$B$34) -> 1329.5892 | R9: =Q9*(1+Assumptions!$B$34) -> 1382.7728
A10: Total Revenue | B10: =SUM(B4:B9) -> 544.673 | C10: =SUM(C4:C9) -> 552.558 | D10: =SUM(D4:D9) -> 631.721 | E10: =SUM(E4:E9) -> 715.1955 | F10: =SUM(F4:F9) -> 798.67 | G10: =SUM(G4:G9) -> 849.438 | H10: =SUM(H4:H9) -> 885.6845 | I10: =SUM(I4:I9) -> 872.933 | ... M10: =SUM(M4:M9) -> 528.1315 | N10: =SUM(B10:M10) -> 8365.3 | O10: =SUM(O4:O9) -> 10079.48 | P10: =SUM(P4:P9) -> 12130.851 | Q10: =SUM(Q4:Q9) -> 14465.389 | R10: =SUM(R4:R9) -> 16688.973
A12: COST OF GOODS SOLD ($000s)
A13: Logistics | B13: =-B4*(1-(Assumptions!C38+Assumptions!$G$177+Assumptions!B117)) -> -237.614 | C13: =-C4*(1-(Assumptions!C38+Assumptions!$G$177+Assumptions!C117)) -> -237.614 | D13: =-D4*(1-(Assumptions!C38+Assumptions!$G$177+Assumptions!D117)) -> -277.7775 | E13: =-E4*(1-(Assumptions!C38+Assumptions!$G$177+Assumptions!E117)) -> -318.903 | F13: =-F4*(1-(Assumptions!C38+Assumptions!$G$177+Assumptions!F117)) -> -360.9905 | G13: =-G4*(1-(Assumptions!C38+Assumptions!$G$177+Assumptions!G117)) -> -384.8 | H13: =-H4*(1-(Assumptions!C38+Assumptions!$G$177+Assumptions!H117)) -> -404.04 | I13: =-I4*(1-(Assumptions!C38+Assumptions!$G$177+Assumptions!J117)) -> -404.04 | J13: =-J4*(1-(Assumptions!C38+Assumptions!$G$177+Assumptions!K117)) -> -360.9905 | K13: =-K4*(1-(Assumptions!C38+Assumptions!$G$177+Assumptions!L117)) -> -300.144 | L13: =-L4*(1-(Assumptions!C38+Assumptions!$G$177+Assumptions!M117)) -> -240.7405 | M13: =-M4*(1-(Assumptions!C38+Assumptions!$G$177+Assumptions!N117)) -> -237.614 | N13: =SUM(B13:M13) -> -3765.268 | O13: =-O4*(1-(Assumptions!D38+Assumptions!$G$177)) -> -4021.16 | P13: =-P4*(1-(Assumptions!E38+Assumptions!$G$177)) -> -4326 | Q13: =-Q4*(1-(Assumptions!F38+Assumptions!$G$177)) -> -4652.38 | R13: =-R4*(1-(Assumptions!G38+Assumptions!$G$177)) -> -5007.07
A14: Field Services | B14: =-B5*(1-(Assumptions!C39+Assumptions!$G$178+Assumptions!B118)) -> -26.7267 | C14: =-C5*(1-(Assumptions!C39+Assumptions!$G$178+Assumptions!C118)) -> -26.7267 | D14: =-D5*(1-(Assumptions!C39+Assumptions!$G$178+Assumptions!D118)) -> -30.22173 | E14: =-E5*(1-(Assumptions!C39+Assumptions!$G$178+Assumptions!E118)) -> -35.532805 | F14: =-F5*(1-(Assumptions!C39+Assumptions!$G$178+Assumptions!F118)) -> -41.118 | G14: =-G5*(1-(Assumptions!C39+Assumptions!$G$178+Assumptions!G118)) -> -44.47597 | H14: =-H5*(1-(Assumptions!C39+Assumptions!$G$178+Assumptions!H118)) -> -46.497605 | I14: =-I5*(1-(Assumptions!C39+Assumptions!$G$178+Assumptions!J118)) -> -44.47597 | J14: =-J5*(1-(Assumptions!C39+Assumptions!$G$178+Assumptions!K118)) -> -39.713135 | K14: =-K5*(1-(Assumptions!C39+Assumptions!$G$178+Assumptions!L118)) -> -32.380425 | L14: =-L5*(1-(Assumptions!C39+Assumptions!$G$178+Assumptions!M118)) -> -28.50848 | M14: =-M5*(1-(Assumptions!C39+Assumptions!$G$178+Assumptions!N118)) -> -24.499475 | N14: =SUM(B14:M14) -> -420.877 | O14: =-O5*(1-(Assumptions!D39+Assumptions!$G$178)) -> -604.296 | P14: =-P5*(1-(Assumptions!E39+Assumptions!$G$178)) -> -785.862 | Q14: =-Q5*(1-(Assumptions!F39+Assumptions!$G$178)) -> -967.076 | R14: =-R5*(1-(Assumptions!G39+Assumptions!$G$178)) -> -1142.042
A15: Installations | B15: =-B6*(1-(Assumptions!C40+Assumptions!$G$181+Assumptions!B119)) -> -43.89 | C15: =-C6*(1-(Assumptions!C40+Assumptions!$G$181+Assumptions!C119)) -> -47.88 | D15: =-D6*(1-(Assumptions!C40+Assumptions!$G$181+Assumptions!D119)) -> -58.8 | E15: =-E6*(1-(Assumptions!C40+Assumptions!$G$181+Assumptions!E119)) -> -68.04 | F15: =-F6*(1-(Assumptions!C40+Assumptions!$G$181+Assumptions!F119)) -> -77.91 | G15: =-G6*(1-(Assumptions!C40+Assumptions!$G$181+Assumptions!G119)) -> -85.33 | H15: =-H6*(1-(Assumptions!C40+Assumptions!$G$181+Assumptions!H119)) -> -89.04 | I15: =-I6*(1-(Assumptions!C40+Assumptions!$G$181+Assumptions!J119)) -> -85.33 | J15: =-J6*(1-(Assumptions!C40+Assumptions!$G$181+Assumptions!K119)) -> -73.15 | K15: =-K6*(1-(Assumptions!C40+Assumptions!$G$181+Assumptions!L119)) -> -58.8 | L15: =-L6*(1-(Assumptions!C40+Assumptions!$G$181+Assumptions!M119)) -> -39.2 | M15: =-M6*(1-(Assumptions!C40+Assumptions!$G$181+Assumptions!N119)) -> -35.91 | N15: =SUM(B15:M15) -> -763.28 | O15: =-O6*(1-(Assumptions!D40+Assumptions!$G$181)) -> -1211.65 | P15: =-P6*(1-(Assumptions!E40+Assumptions!$G$181)) -> -1784.16 | Q15: =-Q6*(1-(Assumptions!F40+Assumptions!$G$181)) -> -2498.04 | R15: =-R6*(1-(Assumptions!G40+Assumptions!$G$181)) -> -3064.46
A16: Apollo Fleet Services | B16: =-B7*(1-(Assumptions!C41+Assumptions!$G$179+Assumptions!B120)) -> -6.24375 | C16: =-C7*(1-(Assumptions!C41+Assumptions!$G$179+Assumptions!C120)) -> -6.24375 | D16: =-D7*(1-(Assumptions!C41+Assumptions!$G$179+Assumptions!D120)) -> -6.66 | E16: =-E7*(1-(Assumptions!C41+Assumptions!$G$179+Assumptions!E120)) -> -7.07625 | F16: =-F7*(1-(Assumptions!C41+Assumptions!$G$179+Assumptions!F120)) -> -7.4925 | G16: =-G7*(1-(Assumptions!C41+Assumptions!$G$179+Assumptions!G120)) -> -7.90875 | H16: =-H7*(1-(Assumptions!C41+Assumptions!$G$179+Assumptions!H120)) -> -7.90875 | I16: =-I7*(1-(Assumptions!C41+Assumptions!$G$179+Assumptions!J120)) -> -7.4925 | J16: =-J7*(1-(Assumptions!C41+Assumptions!$G$179+Assumptions!K120)) -> -7.07625 | K16: =-K7*(1-(Assumptions!C41+Assumptions!$G$179+Assumptions!L120)) -> -6.66 | L16: =-L7*(1-(Assumptions!C41+Assumptions!$G$179+Assumptions!M120)) -> -6.24375 | M16: =-M7*(1-(Assumptions!C41+Assumptions!$G$179+Assumptions!N120)) -> -6.24375 | N16: =SUM(B16:M16) -> -83.25 | O16: =-O7*(1-(Assumptions!D41+Assumptions!$G$179)) -> -121.91 | P16: =-P7*(1-(Assumptions!E41+Assumptions!$G$179)) -> -168.48 | Q16: =-Q7*(1-(Assumptions!F41+Assumptions!$G$179)) -> -215.84 | R16: =-R7*(1-(Assumptions!G41+Assumptions!$G$179)) -> -266
A17: Apollo Power Management | B17: =-B8*(1-(Assumptions!C42+Assumptions!$G$180+Assumptions!B121)) -> -5.4516 | C17: =-C8*(1-(Assumptions!C42+Assumptions!$G$180+Assumptions!C121)) -> -6.13305 | D17: =-D8*(1-(Assumptions!C42+Assumptions!$G$180+Assumptions!D121)) -> -8.0712 | E17: =-E8*(1-(Assumptions!C42+Assumptions!$G$180+Assumptions!E121)) -> -10.7616 | F17: =-F8*(1-(Assumptions!C42+Assumptions!$G$180+Assumptions!F121)) -> -13.098 | G17: =-G8*(1-(Assumptions!C42+Assumptions!$G$180+Assumptions!G121)) -> -16.5672 | H17: =-H8*(1-(Assumptions!C42+Assumptions!$G$180+Assumptions!H121)) -> -17.8416 | I17: =-I8*(1-(Assumptions!C42+Assumptions!$G$180+Assumptions!J121)) -> -16.7973 | J17: =-J8*(1-(Assumptions!C42+Assumptions!$G$180+Assumptions!K121)) -> -13.098 | K17: =-K8*(1-(Assumptions!C42+Assumptions!$G$180+Assumptions!L121)) -> -10.089 | L17: =-L8*(1-(Assumptions!C42+Assumptions!$G$180+Assumptions!M121)) -> -7.3986 | M17: =-M8*(1-(Assumptions!C42+Assumptions!$G$180+Assumptions!N121)) -> -6.13305 | N17: =SUM(B17:M17) -> -131.4402 | O17: =-O8*(1-(Assumptions!D42+Assumptions!$G$180)) -> -167.9 | P17: =-P8*(1-(Assumptions!E42+Assumptions!$G$180)) -> -212.29 | Q17: =-Q8*(1-(Assumptions!F42+Assumptions!$G$180)) -> -251.3 | R17: =-R8*(1-(Assumptions!G42+Assumptions!$G$180)) -> -284.97
A18: Brokerage | B18: =-B9*(1-Assumptions!$B$31) -> -83.725 | C18: =-C9*(1-Assumptions!$B$31) -> -83.725 | D18: =-D9*(1-Assumptions!$B$31) -> -83.725 | E18: =-E9*(1-Assumptions!$B$31) -> -83.725 | F18: =-F9*(1-Assumptions!$B$31) -> -83.725 | G18: =-G9*(1-Assumptions!$B$31) -> -83.725 | H18: =-H9*(1-Assumptions!$B$31) -> -83.725 | I18: =-I9*(1-Assumptions!$B$31) -> -83.725 | ... M18: =-M9*(1-Assumptions!$B$31) -> -83.725 | N18: =SUM(B18:M18) -> -1004.7 | O18: =-O9*(1-Assumptions!$B$31) -> -1044.888 | P18: =-P9*(1-Assumptions!$B$31) -> -1086.6835 | Q18: =-Q9*(1-Assumptions!$B$31) -> -1130.1509 | R18: =-R9*(1-Assumptions!$B$31) -> -1175.3569
A19: Total COGS | B19: =SUM(B13:B18) -> -403.65105 | C19: =SUM(C13:C18) -> -408.3225 | D19: =SUM(D13:D18) -> -465.25543 | E19: =SUM(E13:E18) -> -524.03866 | F19: =SUM(F13:F18) -> -584.334 | G19: =SUM(G13:G18) -> -622.80692 | H19: =SUM(H13:H18) -> -649.05295 | I19: =SUM(I13:I18) -> -641.86077 | ... M19: =SUM(M13:M18) -> -394.12528 | N19: =SUM(B19:M19) -> -6168.8152 | O19: =SUM(O13:O18) -> -7171.804 | P19: =SUM(P13:P18) -> -8363.4755 | Q19: =SUM(Q13:Q18) -> -9714.7869 | R19: =SUM(R13:R18) -> -10939.899
A20: Gross Margin % | B20: =1+B19/B10 -> 0.25891122 | C20: =1+C19/C10 -> 0.26103233 | D20: =1+D19/D10 -> 0.26351122 | E20: =1+E19/E10 -> 0.26727915 | F20: =1+F19/F10 -> 0.26836616 | G20: =1+G19/G10 -> 0.2668012 | H20: =1+H19/H10 -> 0.26717363 | I20: =1+I19/I10 -> 0.26470786 | ... R20: =1+R19/R10 -> 0.34448339
A22: GROSS PROFIT ($000s)
A23: Gross Profit | B23: =B10+B19 -> 141.02195 | C23: =C10+C19 -> 144.2355 | D23: =D10+D19 -> 166.46557 | E23: =E10+E19 -> 191.15684 | F23: =F10+F19 -> 214.336 | G23: =G10+G19 -> 226.63108 | H23: =H10+H19 -> 236.63154 | I23: =I10+I19 -> 231.07223 | ... R23: =R10+R19 -> 5749.0739
A24: Gross Margin % | B24: =B23/B10 -> 0.25891122 | C24: =C23/C10 -> 0.26103233 | D24: =D23/D10 -> 0.26351122 | E24: =E23/E10 -> 0.26727915 | F24: =F23/F10 -> 0.26836616 | G24: =G23/G10 -> 0.2668012 | H24: =H23/H10 -> 0.26717363 | I24: =I23/I10 -> 0.26470786 | ... R24: =R23/R10 -> 0.34448339
A25: Apollo Energy Resources — Confidential | Revenue Build | Mar 2026

Sheet Income Statement
A1: APOLLO ENERGY RESOURCES — CONSOLIDATED INCOME STATEMENT ($000s)
B2: 46048 | C2: 46079 | D2: 46107 | E2: 46138 | F2: 46168 | G2: 46199 | H2: 46229 | I2: 46260 | J2: 46291 | K2: 46321 | L2: 46352 | M2: 46382 | N2: FY2026 | O2: FY2027 | P2: FY2028 | Q2: FY2029 | R2: FY2030
A3: Revenue | B3: ='Revenue Build'!B10 -> 544.673 | C3: ='Revenue Build'!C10 -> 552.558 | D3: ='Revenue Build'!D10 -> 631.721 | E3: ='Revenue Build'!E10 -> 715.1955 | F3: ='Revenue Build'!F10 -> 798.67 | G3: ='Revenue Build'!G10 -> 849.438 | H3: ='Revenue Build'!H10 -> 885.6845 | I3: ='Revenue Build'!I10 -> 872.933 | ... M3: ='Revenue Build'!M10 -> 528.1315 | N3: =SUM(B3:M3) -> 8365.3 | O3: ='Revenue Build'!O10 -> 10079.48 | P3: ='Revenue Build'!P10 -> 12130.851 | Q3: ='Revenue Build'!Q10 -> 14465.389 | R3: ='Revenue Build'!R10 -> 16688.973
A4: Cost of Goods Sold | B4: ='Revenue Build'!B19 -> -403.65105 | C4: ='Revenue Build'!C19 -> -408.3225 | D4: ='Revenue Build'!D19 -> -465.25543 | E4: ='Revenue Build'!E19 -> -524.03866 | F4: ='Revenue Build'!F19 -> -584.334 | G4: ='Revenue Build'!G19 -> -622.80692 | H4: ='Revenue Build'!H19 -> -649.05295 | I4: ='Revenue Build'!I19 -> -641.86077 | ... M4: ='Revenue Build'!M19 -> -394.12528 | N4: =SUM(B4:M4) -> -6168.8152 | O4: ='Revenue Build'!O19 -> -7171.804 | P4: ='Revenue Build'!P19 -> -8363.4755 | Q4: ='Revenue Build'!Q19 -> -9714.7869 | R4: ='Revenue Build'!R19 -> -10939.899
A5: Gross Profit | B5: =B3+B4 -> 141.02195 | C5: =C3+C4 -> 144.2355 | D5: =D3+D4 -> 166.46557 | E5: =E3+E4 -> 191.15684 | F5: =F3+F4 -> 214.336 | G5: =G3+G4 -> 226.63108 | H5: =H3+H4 -> 236.63154 | I5: =I3+I4 -> 231.07223 | ... R5: =R3+R4 -> 5749.0739
A6: Gross Margin % | B6: =B5/B3 -> 0.25891122 | C6: =C5/C3 -> 0.26103233 | D6: =D5/D3 -> 0.26351122 | E6: =E5/E3 -> 0.26727915 | F6: =F5/F3 -> 0.26836616 | G6: =G5/G3 -> 0.2668012 | H6: =H5/H3 -> 0.26717363 | I6: =I5/I3 -> 0.26470786 | ... R6: =R5/R3 -> 0.34448339
A8: Operating Expenses:
A9: Insurance — Total | B9: =Assumptions!$C50*Assumptions!$G$158*(0.7/12+0.3*'Revenue Build'!B10/'Revenue Build'!$N10) -> 48.666645 | C9: =Assumptions!$C50*Assumptions!$G$158*(0.7/12+0.3*'Revenue Build'!C10/'Revenue Build'!$N10) -> 48.843379 | D9: =Assumptions!$C50*Assumptions!$G$158*(0.7/12+0.3*'Revenue Build'!D10/'Revenue Build'!$N10) -> 50.61774 | E9: =Assumptions!$C50*Assumptions!$G$158*(0.7/12+0.3*'Revenue Build'!E10/'Revenue Build'!$N10) -> 52.488739 | F9: =Assumptions!$C50*Assumptions!$G$158*(0.7/12+0.3*'Revenue Build'!F10/'Revenue Build'!$N10) -> 54.359739 | G9: =Assumptions!$C50*Assumptions!$G$158*(0.7/12+0.3*'Revenue Build'!G10/'Revenue Build'!$N10) -> 55.497654 | H9: =Assumptions!$C50*Assumptions!$G$158*(0.7/12+0.3*'Revenue Build'!H10/'Revenue Build'!$N10) -> 56.310083 | I9: =Assumptions!$C50*Assumptions!$G$158*(0.7/12+0.3*'Revenue Build'!I10/'Revenue Build'!$N10) -> 56.024271 | ... M9: =Assumptions!$C50*Assumptions!$G$158*(0.7/12+0.3*'Revenue Build'!M10/'Revenue Build'!$N10) -> 48.295883 | N9: =SUM(B9:M9) -> 625 | O9: =Assumptions!D50*Assumptions!$G$158 -> 656 | P9: =Assumptions!E50*Assumptions!$G$158 -> 688 | Q9: =Assumptions!F50*Assumptions!$G$158 -> 723 | R9: =Assumptions!G50*Assumptions!$G$158 -> 759
A10: Back-Office / Admin Payroll | B10: =Assumptions!$C52*(0.7/12+0.3*'Revenue Build'!B10/'Revenue Build'!$N10) -> 16.274126 | C10: =Assumptions!$C52*(0.7/12+0.3*'Revenue Build'!C10/'Revenue Build'!$N10) -> 16.333226 | D10: =Assumptions!$C52*(0.7/12+0.3*'Revenue Build'!D10/'Revenue Build'!$N10) -> 16.926572 | E10: =Assumptions!$C52*(0.7/12+0.3*'Revenue Build'!E10/'Revenue Build'!$N10) -> 17.552234 | F10: =Assumptions!$C52*(0.7/12+0.3*'Revenue Build'!F10/'Revenue Build'!$N10) -> 18.177897 | G10: =Assumptions!$C52*(0.7/12+0.3*'Revenue Build'!G10/'Revenue Build'!$N10) -> 18.558415 | H10: =Assumptions!$C52*(0.7/12+0.3*'Revenue Build'!H10/'Revenue Build'!$N10) -> 18.830092 | I10: =Assumptions!$C52*(0.7/12+0.3*'Revenue Build'!I10/'Revenue Build'!$N10) -> 18.734516 | ... M10: =Assumptions!$C52*(0.7/12+0.3*'Revenue Build'!M10/'Revenue Build'!$N10) -> 16.150143 | N10: =SUM(B10:M10) -> 209 | O10: =Assumptions!D52 -> 252 | P10: =Assumptions!E52 -> 291 | Q10: =Assumptions!F52 -> 333 | R10: =Assumptions!G52 -> 367
A11: Corporate Overhead (G&A) | B11: =Assumptions!$C53*(0.7/12+0.3*'Revenue Build'!B10/'Revenue Build'!$N10) -> 6.2293305 | C11: =Assumptions!$C53*(0.7/12+0.3*'Revenue Build'!C10/'Revenue Build'!$N10) -> 6.2519526 | D11: =Assumptions!$C53*(0.7/12+0.3*'Revenue Build'!D10/'Revenue Build'!$N10) -> 6.4790708 | E11: =Assumptions!$C53*(0.7/12+0.3*'Revenue Build'!E10/'Revenue Build'!$N10) -> 6.7185586 | F11: =Assumptions!$C53*(0.7/12+0.3*'Revenue Build'!F10/'Revenue Build'!$N10) -> 6.9580465 | G11: =Assumptions!$C53*(0.7/12+0.3*'Revenue Build'!G10/'Revenue Build'!$N10) -> 7.1036996 | H11: =Assumptions!$C53*(0.7/12+0.3*'Revenue Build'!H10/'Revenue Build'!$N10) -> 7.2076907 | I11: =Assumptions!$C53*(0.7/12+0.3*'Revenue Build'!I10/'Revenue Build'!$N10) -> 7.1711067 | ... M11: =Assumptions!$C53*(0.7/12+0.3*'Revenue Build'!M10/'Revenue Build'!$N10) -> 6.1818731 | N11: =SUM(B11:M11) -> 80 | O11: =Assumptions!D53 -> 84 | P11: =Assumptions!E53 -> 88 | Q11: =Assumptions!F53 -> 92 | R11: =Assumptions!G53 -> 97
A12: Sales & Marketing | B12: =Assumptions!$C54*(0.7/12+0.3*'Revenue Build'!B10/'Revenue Build'!$N10) -> 6.2293305 | C12: =Assumptions!$C54*(0.7/12+0.3*'Revenue Build'!C10/'Revenue Build'!$N10) -> 6.2519526 | D12: =Assumptions!$C54*(0.7/12+0.3*'Revenue Build'!D10/'Revenue Build'!$N10) -> 6.4790708 | E12: =Assumptions!$C54*(0.7/12+0.3*'Revenue Build'!E10/'Revenue Build'!$N10) -> 6.7185586 | F12: =Assumptions!$C54*(0.7/12+0.3*'Revenue Build'!F10/'Revenue Build'!$N10) -> 6.9580465 | G12: =Assumptions!$C54*(0.7/12+0.3*'Revenue Build'!G10/'Revenue Build'!$N10) -> 7.1036996 | H12: =Assumptions!$C54*(0.7/12+0.3*'Revenue Build'!H10/'Revenue Build'!$N10) -> 7.2076907 | I12: =Assumptions!$C54*(0.7/12+0.3*'Revenue Build'!I10/'Revenue Build'!$N10) -> 7.1711067 | ... M12: =Assumptions!$C54*(0.7/12+0.3*'Revenue Build'!M10/'Revenue Build'!$N10) -> 6.1818731 | N12: =SUM(B12:M12) -> 80 | O12: =Assumptions!D54 -> 80 | P12: =Assumptions!E54 -> 100 | Q12: =Assumptions!F54 -> 120 | R12: =Assumptions!G54 -> 150
A13: Software / Hardware / IT | B13: =Assumptions!$C55*(0.7/12+0.3*'Revenue Build'!B10/'Revenue Build'!$N10) -> 3.8933316 | C13: =Assumptions!$C55*(0.7/12+0.3*'Revenue Build'!C10/'Revenue Build'!$N10) -> 3.9074703 | D13: =Assumptions!$C55*(0.7/12+0.3*'Revenue Build'!D10/'Revenue Build'!$N10) -> 4.0494192 | E13: =Assumptions!$C55*(0.7/12+0.3*'Revenue Build'!E10/'Revenue Build'!$N10) -> 4.1990992 | F13: =Assumptions!$C55*(0.7/12+0.3*'Revenue Build'!F10/'Revenue Build'!$N10) -> 4.3487791 | G13: =Assumptions!$C55*(0.7/12+0.3*'Revenue Build'!G10/'Revenue Build'!$N10) -> 4.4398123 | H13: =Assumptions!$C55*(0.7/12+0.3*'Revenue Build'!H10/'Revenue Build'!$N10) -> 4.5048067 | I13: =Assumptions!$C55*(0.7/12+0.3*'Revenue Build'!I10/'Revenue Build'!$N10) -> 4.4819417 | ... M13: =Assumptions!$C55*(0.7/12+0.3*'Revenue Build'!M10/'Revenue Build'!$N10) -> 3.8636707 | N13: =SUM(B13:M13) -> 50 | O13: =Assumptions!D55 -> 35 | P13: =Assumptions!E55 -> 35 | Q13: =Assumptions!F55 -> 40 | R13: =Assumptions!G55 -> 40
A14: Depreciation & Amortization | B14: =Assumptions!C56/12 -> 38.833333 | C14: =Assumptions!C56/12 -> 38.833333 | D14: =Assumptions!C56/12 -> 38.833333 | E14: =Assumptions!C56/12 -> 38.833333 | F14: =Assumptions!C56/12 -> 38.833333 | G14: =Assumptions!C56/12 -> 38.833333 | H14: =Assumptions!C56/12 -> 38.833333 | I14: =Assumptions!C56/12 -> 38.833333 | J14: =Assumptions!C56/12 -> 38.833333 | K14: =Assumptions!C56/12 -> 38.833333 | L14: =Assumptions!C56/12 -> 38.833333 | M14: =Assumptions!C56/12 -> 38.833333 | N14: =SUM(B14:M14)+80 -> 546 | O14: =Assumptions!D56+80 -> 714 | P14: =Assumptions!E56+80 -> 914 | Q14: =Assumptions!F56+80 -> 1144 | R14: =Assumptions!G56+80 -> 1372
A16: Total Operating Expenses | B16: =SUM(B9:B14) -> 120.1261 | C16: =SUM(C9:C14) -> 120.42131 | D16: =SUM(D9:D14) -> 123.38521 | E16: =SUM(E9:E14) -> 126.51052 | F16: =SUM(F9:F14) -> 129.63584 | G16: =SUM(G9:G14) -> 131.53661 | H16: =SUM(H9:H14) -> 132.8937 | I16: =SUM(I9:I14) -> 132.41628 | ... R16: =SUM(R9:R14) -> 2785
A17: OpEx as % of Revenue | B17: =B16/B3 -> 0.22054718 | C17: =C16/C3 -> 0.21793425 | D17: =D16/D3 -> 0.19531598 | E17: =E16/E3 -> 0.17688943 | F17: =F16/F3 -> 0.16231465 | G17: =G16/G3 -> 0.15485134 | H17: =H16/H3 -> 0.15004632 | I17: =I16/I3 -> 0.15169122 | ... R17: =R16/R3 -> 0.16687666
A19: EBIT (Operating Income) | B19: =B5-B16 -> 20.895853 | C19: =C5-C16 -> 23.814186 | D19: =D5-D16 -> 43.080363 | E19: =E5-E16 -> 64.646321 | F19: =F5-F16 -> 84.700159 | G19: =G5-G16 -> 95.094466 | H19: =H5-H16 -> 103.73785 | I19: =I5-I16 -> 98.655955 | ... R19: =R5-R16 -> 2964.0739
A20: EBIT Margin % | B20: =B19/B3 -> 0.038364034 | C20: =C19/C3 -> 0.043098075 | D20: =D19/D3 -> 0.068195237 | E20: =E19/E3 -> 0.09038972 | F20: =F19/F3 -> 0.10605151 | G20: =G19/G3 -> 0.11194986 | H20: =H19/H3 -> 0.11712732 | I20: =I19/I3 -> 0.11301664 | ... R20: =R19/R3 -> 0.17760673
A22: Interest Expense | B22: ='Debt Schedule'!B69 -> 18.458333 | C22: ='Debt Schedule'!C69 -> 18.157066 | D22: ='Debt Schedule'!D69 -> 17.853865 | E22: ='Debt Schedule'!E69 -> 17.548719 | F22: ='Debt Schedule'!F69 -> 21.616614 | G22: ='Debt Schedule'!G69 -> 21.246142 | H22: ='Debt Schedule'!H69 -> 20.873327 | I22: ='Debt Schedule'!I69 -> 20.498156 | ... R22: ='Debt Schedule'!R69 -> 107.56207
A23: Other Income / Corporate Adjustment | B23: 0 | C23: 0 | D23: 0 | E23: 0 | F23: 0 | G23: 0 | H23: 0 | I23: 0 | J23: 0 | K23: 0 | L23: 0 | M23: 0 | N23: =SUM(B23:M23) -> 0 | O23: 0 | P23: 0 | Q23: 0 | R23: 0
A24: EBT (Earnings Before Tax) | B24: =B19-B22+B23 -> 2.4375199 | C24: =C19-C22+C23 -> 5.6571199 | D24: =D19-D22+D23 -> 25.226498 | E24: =E19-E22+E23 -> 47.097603 | F24: =F19-F22+F23 -> 63.083546 | G24: =G19-G22+G23 -> 73.848325 | H24: =H19-H22+H23 -> 82.864521 | I24: =I19-I22+I23 -> 78.157799 | ... R24: =R19-R22+R23 -> 2856.5119
A25: Tax Distributions (Pass-Through) | B25: =IF(B24>0,B24*Assumptions!$B$13,0) -> 0.75563118 | C25: =IF(C24>0,C24*Assumptions!$B$13,0) -> 1.7537072 | D25: =IF(D24>0,D24*Assumptions!$B$13,0) -> 7.8202143 | E25: =IF(E24>0,E24*Assumptions!$B$13,0) -> 14.600257 | F25: =IF(F24>0,F24*Assumptions!$B$13,0) -> 19.555899 | G25: =IF(G24>0,G24*Assumptions!$B$13,0) -> 22.892981 | H25: =IF(H24>0,H24*Assumptions!$B$13,0) -> 25.688002 | I25: =IF(I24>0,I24*Assumptions!$B$13,0) -> 24.228918 | ... R25: =IF(R24>0,R24*Assumptions!$B$13,0) -> 885.51868
A27: Net Income | B27: =B24-B25 -> 1.6818888 | C27: =C24-C25 -> 3.9034127 | D27: =D24-D25 -> 17.406284 | E27: =E24-E25 -> 32.497346 | F27: =F24-F25 -> 43.527647 | G27: =G24-G25 -> 50.955344 | H27: =H24-H25 -> 57.17652 | I27: =I24-I25 -> 53.928881 | ... R27: =R24-R25 -> 1970.9932
A28: Net Margin % | B28: =B27/B3 -> 0.0030878872 | C28: =C27/C3 -> 0.0070642589 | D28: =D27/D3 -> 0.027553752 | E28: =E27/E3 -> 0.045438409 | F28: =F27/F3 -> 0.054500165 | G28: =G27/G3 -> 0.059987126 | H28: =H27/H3 -> 0.064556306 | I28: =I27/I3 -> 0.061778947 | ... R28: =R27/R3 -> 0.11810153
A30: EBITDA | B30: =B19+B14 -> 59.729187 | C30: =C19+C14 -> 62.647519 | D30: =D19+D14 -> 81.913697 | E30: =E19+E14 -> 103.47965 | F30: =F19+F14 -> 123.53349 | G30: =G19+G14 -> 133.9278 | H30: =H19+H14 -> 142.57118 | I30: =I19+I14 -> 137.48929 | ... R30: =R19+R14 -> 4336.0739
A32: Apollo Energy Resources — Confidential | Income Statement | Mar 2026

Sheet Balance Sheet
A1: APOLLO ENERGY RESOURCES — BALANCE SHEET ($000s)
B2: Opening | C2: 46048 | D2: 46079 | E2: 46107 | F2: 46138 | G2: 46168 | H2: 46199 | I2: 46229 | J2: 46260 | K2: 46291 | L2: 46321 | M2: 46352 | N2: 46382 | O2: FY2027E | P2: FY2028E | Q2: FY2029E | R2: FY2030E
A3: ASSETS
A4: Current Assets
A5: Cash & Cash Equivalents | B5: =Assumptions!B127 -> 34 | C5: =C47-C6-C7-C8-C9-C15-C16-C17-C18-C19-C20-C21-C23 -> 3225.3222 | D5: =D47-D6-D7-D8-D9-D15-D16-D17-D18-D19-D20-D21-D23 -> 3149.3647 | E5: =E47-E6-E7-E8-E9-E15-E16-E17-E18-E19-E20-E21-E23 -> 3000.3916 | F5: =F47-F6-F7-F8-F9-F15-F16-F17-F18-F19-F20-F21-F23 -> 2861.8462 | G5: =G47-G6-G7-G8-G9-G15-G16-G17-G18-G19-G20-G21-G23 -> 3458.5063 | H5: =H47-H6-H7-H8-H9-H15-H16-H17-H18-H19-H20-H21-H23 -> 3342.5552 | I5: =I47-I6-I7-I8-I9-I15-I16-I17-I18-I19-I20-I21-I23 -> 3229.8925 | J5: =J47-J6-J7-J8-J9-J15-J16-J17-J18-J19-J20-J21-J23 -> 3138.8993 | ... M5: =M47-M6-M7-M8-M9-M15-M16-M17-M18-M19-M20-M21-M23 -> 2762.1768 | N5: ='Cash Flow'!N36 -> 2631.0098 | O5: ='Cash Flow'!O36 -> 1024.4751 | P5: ='Cash Flow'!P36 -> 836.37422 | Q5: ='Cash Flow'!Q36 -> 1216.2893 | R5: ='Cash Flow'!R36 -> 2202.2551
A6: Accounts Receivable | B6: =Assumptions!B128 -> 274 | C6: =ROUND('Income Statement'!B3/30*Assumptions!$B$68,0) -> 654 | D6: =ROUND('Income Statement'!C3/30*Assumptions!$B$68,0) -> 663 | E6: =ROUND('Income Statement'!D3/30*Assumptions!$B$68,0) -> 758 | F6: =ROUND('Income Statement'!E3/30*Assumptions!$B$68,0) -> 858 | G6: =ROUND('Income Statement'!F3/30*Assumptions!$B$68,0) -> 958 | H6: =ROUND('Income Statement'!G3/30*Assumptions!$B$68,0) -> 1019 | I6: =ROUND('Income Statement'!H3/30*Assumptions!$B$68,0) -> 1063 | J6: =ROUND('Income Statement'!I3/30*Assumptions!$B$68,0) -> 1048 | ... N6: =ROUND('Income Statement'!M3/30*Assumptions!$B$68,0) -> 634 | O6: =ROUND('Income Statement'!O3*Assumptions!D68/365,0) -> 967 | P6: =ROUND('Income Statement'!P3*Assumptions!E68/365,0) -> 1130 | Q6: =ROUND('Income Statement'!Q3*Assumptions!F68/365,0) -> 1308 | R6: =ROUND('Income Statement'!R3*Assumptions!G68/365,0) -> 1509
A7: Inventory (Fleet Services) | B7: =Assumptions!B129 -> 5 | C7: =ROUND('Revenue Build'!B7*Assumptions!$B$73,0) -> 1 | D7: =ROUND('Revenue Build'!C7*Assumptions!$B$73,0) -> 1 | E7: =ROUND('Revenue Build'!D7*Assumptions!$B$73,0) -> 1 | F7: =ROUND('Revenue Build'!E7*Assumptions!$B$73,0) -> 1 | G7: =ROUND('Revenue Build'!F7*Assumptions!$B$73,0) -> 1 | H7: =ROUND('Revenue Build'!G7*Assumptions!$B$73,0) -> 1 | I7: =ROUND('Revenue Build'!H7*Assumptions!$B$73,0) -> 1 | J7: =ROUND('Revenue Build'!I7*Assumptions!$B$73,0) -> 1 | ... N7: =ROUND('Revenue Build'!M7*Assumptions!$B$73,0) -> 1 | O7: =ROUND('Revenue Build'!O7*Assumptions!$B$73,0) -> 17 | P7: =ROUND('Revenue Build'!P7*Assumptions!$B$73,0) -> 23 | Q7: =ROUND('Revenue Build'!Q7*Assumptions!$B$73,0) -> 30 | R7: =ROUND('Revenue Build'!R7*Assumptions!$B$73,0) -> 38
A8: Prepaid Expenses | B8: =Assumptions!B130 -> 30 | C8: =ROUND('Income Statement'!B16*Assumptions!$B$74,0) -> 4 | D8: =ROUND('Income Statement'!C16*Assumptions!$B$74,0) -> 4 | E8: =ROUND('Income Statement'!D16*Assumptions!$B$74,0) -> 4 | F8: =ROUND('Income Statement'!E16*Assumptions!$B$74,0) -> 4 | G8: =ROUND('Income Statement'!F16*Assumptions!$B$74,0) -> 4 | H8: =ROUND('Income Statement'!G16*Assumptions!$B$74,0) -> 4 | I8: =ROUND('Income Statement'!H16*Assumptions!$B$74,0) -> 4 | J8: =ROUND('Income Statement'!I16*Assumptions!$B$74,0) -> 4 | ... N8: =ROUND('Income Statement'!M16*Assumptions!$B$74,0) -> 4 | O8: =ROUND('Income Statement'!O16*Assumptions!$B$74,0) -> 55 | P8: =ROUND('Income Statement'!P16*Assumptions!$B$74,0) -> 63 | Q8: =ROUND('Income Statement'!Q16*Assumptions!$B$74,0) -> 74 | R8: =ROUND('Income Statement'!R16*Assumptions!$B$74,0) -> 84
A9: Other Current Assets | B9: =Assumptions!B131 -> 41 | C9: =B9 -> 41 | D9: =B9 -> 41 | E9: =B9 -> 41 | F9: =B9 -> 41 | G9: =B9 -> 41 | H9: =B9 -> 41 | I9: =B9 -> 41 | J9: =B9 -> 41 | K9: =B9 -> 41 | L9: =B9 -> 41 | M9: =B9 -> 41 | N9: =ROUND('Income Statement'!N3*Assumptions!$B$35,0) -> 59 | O9: =ROUND('Income Statement'!O3*Assumptions!$B$35,0) -> 71 | P9: =ROUND('Income Statement'!P3*Assumptions!$B$35,0) -> 86 | Q9: =ROUND('Income Statement'!Q3*Assumptions!$B$35,0) -> 102 | R9: =ROUND('Income Statement'!R3*Assumptions!$B$35,0) -> 118
A10: Total Current Assets | B10: =SUM(B5:B9) -> 384 | C10: =SUM(C5:C9) -> 3925.3222 | D10: =SUM(D5:D9) -> 3858.3647 | E10: =SUM(E5:E9) -> 3804.3916 | F10: =SUM(F5:F9) -> 3765.8462 | G10: =SUM(G5:G9) -> 4462.5063 | H10: =SUM(H5:H9) -> 4407.5552 | I10: =SUM(I5:I9) -> 4338.8925 | ... R10: =SUM(R5:R9) -> 3951.2551
A12: Non-Current Assets
A13: PP&E (Gross) | B13: =Assumptions!B134 -> 1733 | C13: =B13+Assumptions!$C$65/12 -> 1828.5 | D13: =C13+Assumptions!$C$65/12 -> 1924 | E13: =D13+Assumptions!$C$65/12 -> 2019.5 | F13: =E13+Assumptions!$C$65/12 -> 2115 | G13: =F13+Assumptions!$C$65/12 -> 2210.5 | H13: =G13+Assumptions!$C$65/12 -> 2306 | I13: =H13+Assumptions!$C$65/12 -> 2401.5 | J13: =I13+Assumptions!$C$65/12 -> 2497 | K13: =J13+Assumptions!$C$65/12+200 -> 2792.5 | L13: =K13+Assumptions!$C$65/12 -> 2888 | M13: =L13+Assumptions!$C$65/12 -> 2983.5 | N13: =M13+Assumptions!$C$65/12 -> 3079 | O13: =N13+Assumptions!$D$65 -> 3916 | P13: =O13+Assumptions!$E$65 -> 4919 | Q13: =P13+Assumptions!$F$65 -> 6070 | R13: =Q13+Assumptions!$G$65 -> 7209
A14: Less: Accumulated Depreciation | B14: =Assumptions!B135 -> -394 | C14: =B14-'Income Statement'!B14 -> -432.83333 | D14: =C14-'Income Statement'!C14 -> -471.66667 | E14: =D14-'Income Statement'!D14 -> -510.5 | F14: =E14-'Income Statement'!E14 -> -549.33333 | G14: =F14-'Income Statement'!F14 -> -588.16667 | H14: =G14-'Income Statement'!G14 -> -627 | I14: =H14-'Income Statement'!H14 -> -665.83333 | J14: =I14-'Income Statement'!I14 -> -704.66667 | ... N14: =M14-'Income Statement'!M14 -> -860 | O14: =N14-Assumptions!$D$56 -> -1494 | P14: =O14-Assumptions!$E$56 -> -2328 | Q14: =P14-Assumptions!$F$56 -> -3392 | R14: =Q14-Assumptions!$G$56 -> -4684
A15: PP&E (Net) | B15: =B13+B14 -> 1339 | C15: =C13+C14 -> 1395.6667 | D15: =D13+D14 -> 1452.3333 | E15: =E13+E14 -> 1509 | F15: =F13+F14 -> 1565.6667 | G15: =G13+G14 -> 1622.3333 | H15: =H13+H14 -> 1679 | I15: =I13+I14 -> 1735.6667 | ... R15: =R13+R14 -> 2525
A16: Goodwill ¹ | B16: 0 | C16: 0 | D16: 0 | E16: 0 | F16: 0 | G16: 0 | H16: 0 | I16: 0 | J16: 0 | K16: 591.82 | L16: =K16 -> 591.82 | M16: =L16 -> 591.82 | N16: =N47-(N10+N15+SUM(N17:N23)) -> 647.01979 | O16: =N16 -> 647.01979 | P16: =O16 -> 647.01979 | Q16: =P16 -> 647.01979 | R16: =Q16 -> 647.01979
A17: Customer Relationships ¹ | B17: 0 | C17: 0 | D17: 0 | E17: 0 | F17: 0 | G17: 0 | H17: 0 | I17: 0 | J17: 0 | K17: 380 | L17: =K17 -> 380 | M17: =L17 -> 380 | N17: =K17-380/10 -> 342 | O17: =N17-380/10 -> 304 | P17: =O17-380/10 -> 266 | Q17: =P17-380/10 -> 228 | R17: =Q17-380/10 -> 190
A18: Assembled Workforce ¹ | B18: 0 | C18: 0 | D18: 0 | E18: 0 | F18: 0 | G18: 0 | H18: 0 | I18: 0 | J18: 0 | K18: 175 | L18: =K18 -> 175 | M18: =L18 -> 175 | N18: =K18-175/10 -> 157.5 | O18: =N18-175/10 -> 140 | P18: =O18-175/10 -> 122.5 | Q18: =P18-175/10 -> 105 | R18: =Q18-175/10 -> 87.5
A19: Backlog / Excess Opportunities ¹ | B19: 0 | C19: 0 | D19: 0 | E19: 0 | F19: 0 | G19: 0 | H19: 0 | I19: 0 | J19: 0 | K19: 145 | L19: =K19 -> 145 | M19: =L19 -> 145 | N19: =K19-145/10 -> 130.5 | O19: =N19-145/10 -> 116 | P19: =O19-145/10 -> 101.5 | Q19: =P19-145/10 -> 87 | R19: =Q19-145/10 -> 72.5
A20: Intangible Assets (Trade Name) ¹ | B20: 0 | C20: 0 | D20: 0 | E20: 0 | F20: 0 | G20: 0 | H20: 0 | I20: 0 | J20: 0 | K20: 100 | L20: =K20 -> 100 | M20: =L20 -> 100 | N20: =K20-100/10 -> 90 | O20: =N20-100/10 -> 80 | P20: =O20-100/10 -> 70 | Q20: =P20-100/10 -> 60 | R20: =Q20-100/10 -> 50
A21: Acquired AR, Inventory & Cash ¹ | B21: 0 | C21: 0 | D21: 0 | E21: 0 | F21: 0 | G21: 0 | H21: 0 | I21: 0 | J21: 0 | K21: 400 | L21: =K21 -> 400 | M21: =L21 -> 400 | N21: =M21 -> 400 | O21: =N21 -> 400 | P21: =O21 -> 400 | Q21: =P21 -> 400 | R21: =Q21 -> 400
A22: ¹ Installations Acquisition — See Assumptions
A23: Other Long-Term Assets | B23: =Assumptions!B137 -> 50 | C23: =B23 -> 50 | D23: =C23 -> 50 | E23: =D23 -> 50 | F23: =E23 -> 50 | G23: =F23 -> 50 | H23: =G23 -> 50 | I23: =H23 -> 50 | J23: =I23 -> 50 | ... N23: =M23 -> 50 | O23: =ROUND('Income Statement'!O3*($B$23/Assumptions!$B$29),0) -> 87 | P23: =ROUND('Income Statement'!P3*($B$23/Assumptions!$B$29),0) -> 104 | Q23: =ROUND('Income Statement'!Q3*($B$23/Assumptions!$B$29),0) -> 124 | R23: =ROUND('Income Statement'!R3*($B$23/Assumptions!$B$29),0) -> 144
A24: Total Non-Current Assets | B24: =SUM(B15:B23) -> 1389 | C24: =SUM(C15:C23) -> 1445.6667 | D24: =SUM(D15:D23) -> 1502.3333 | E24: =SUM(E15:E23) -> 1559 | F24: =SUM(F15:F23) -> 1615.6667 | G24: =SUM(G15:G23) -> 1672.3333 | H24: =SUM(H15:H23) -> 1729 | I24: =SUM(I15:I23) -> 1785.6667 | ... R24: =SUM(R15:R23) -> 4116.0198
A26: TOTAL ASSETS | B26: =B10+B24 -> 1773 | C26: =C10+C24 -> 5370.9889 | D26: =D10+D24 -> 5360.698 | E26: =E10+E24 -> 5363.3916 | F26: =F10+F24 -> 5381.5129 | G26: =G10+G24 -> 6134.8397 | H26: =H10+H24 -> 6136.5552 | I26: =I10+I24 -> 6124.5591 | ... R26: =R10+R24 -> 8067.2749
A28: LIABILITIES
A29: Current Liabilities
A30: Accounts Payable | B30: =Assumptions!B141 -> 201 | C30: =ROUND(-'Income Statement'!C4/30*Assumptions!$B$69,0) -> 245 | D30: =ROUND(-'Income Statement'!D4/30*Assumptions!$B$69,0) -> 279 | E30: =ROUND(-'Income Statement'!E4/30*Assumptions!$B$69,0) -> 314 | F30: =ROUND(-'Income Statement'!F4/30*Assumptions!$B$69,0) -> 351 | G30: =ROUND(-'Income Statement'!G4/30*Assumptions!$B$69,0) -> 374 | H30: =ROUND(-'Income Statement'!H4/30*Assumptions!$B$69,0) -> 389 | I30: =ROUND(-'Income Statement'!I4/30*Assumptions!$B$69,0) -> 385 | J30: =ROUND(-'Income Statement'!J4/30*Assumptions!$B$69,0) -> 347 | ... M30: =ROUND(-'Income Statement'!M4/30*Assumptions!$B$69,0) -> 236 | N30: =ROUND(-'Income Statement'!M4/30*Assumptions!$B$69,0) -> 236 | O30: =ROUND(-'Income Statement'!O4*Assumptions!D69/365,0) -> 354 | P30: =ROUND(-'Income Statement'!P4*Assumptions!E69/365,0) -> 412 | Q30: =ROUND(-'Income Statement'!Q4*Assumptions!F69/365,0) -> 479 | R30: =ROUND(-'Income Statement'!R4*Assumptions!G69/365,0) -> 540
A31: Accrued Expenses | B31: =Assumptions!B142 -> 25 | C31: =B31 -> 25 | D31: =C31 -> 25 | E31: =D31 -> 25 | F31: =E31 -> 25 | G31: =F31 -> 25 | H31: =G31 -> 25 | I31: =H31 -> 25 | J31: =I31 -> 25 | ... N31: =M31 -> 25 | O31: =ROUND(N31*('Income Statement'!O3/'Income Statement'!N3),0) -> 30 | P31: =ROUND(O31*('Income Statement'!P3/'Income Statement'!O3),0) -> 36 | Q31: =ROUND(P31*('Income Statement'!Q3/'Income Statement'!P3),0) -> 43 | R31: =ROUND(Q31*('Income Statement'!R3/'Income Statement'!Q3),0) -> 50
A32: Current Portion of LTD | B32: 0 | C32: 0 | D32: 0 | E32: 0 | F32: 0 | G32: 0 | H32: 0 | I32: 0 | J32: 0 | K32: 0 | L32: 0 | M32: 0 | N32: =MIN('Debt Schedule'!O70,'Debt Schedule'!N68) -> 1034.7636 | O32: =MIN('Debt Schedule'!P70,'Debt Schedule'!O68) -> 844.52971 | P32: =MIN('Debt Schedule'!Q70,'Debt Schedule'!P68) -> 792.36739 | Q32: =MIN('Debt Schedule'!R70,'Debt Schedule'!Q68) -> 853.63793 | R32: =MAX(0,'Debt Schedule'!R68) -> 477.06525
A33: Total Current Liabilities | B33: =SUM(B30:B32) -> 226 | C33: =SUM(C30:C32) -> 270 | D33: =SUM(D30:D32) -> 304 | E33: =SUM(E30:E32) -> 339 | F33: =SUM(F30:F32) -> 376 | G33: =SUM(G30:G32) -> 399 | H33: =SUM(H30:H32) -> 414 | I33: =SUM(I30:I32) -> 410 | ... R33: =SUM(R30:R32) -> 1067.0653
A35: Non-Current Liabilities
A36: Long-Term Debt | B36: =Assumptions!B86 -> 800 | C36: ='Debt Schedule'!B68 -> 2852.4583 | D36: ='Debt Schedule'!C68 -> 2804.6154 | E36: ='Debt Schedule'!D68 -> 2756.4693 | F36: ='Debt Schedule'!E68 -> 2708.018 | G36: ='Debt Schedule'!F68 -> 3398.7346 | H36: ='Debt Schedule'!G68 -> 3339.0807 | I36: ='Debt Schedule'!H68 -> 3279.0541 | J36: ='Debt Schedule'!I68 -> 3218.6522 | ... M36: ='Debt Schedule'!L68 -> 4688.0616 | N36: ='Debt Schedule'!N68-N32 -> 3567.6003 | O36: ='Debt Schedule'!O68-O32 -> 2123.0706 | P36: ='Debt Schedule'!P68-P32 -> 1330.7032 | Q36: ='Debt Schedule'!Q68-Q32 -> 477.06525 | R36: ='Debt Schedule'!R68-R32 -> 0
A37: Total Non-Current Liabilities | B37: =B36 -> 800 | C37: =C36 -> 2852.4583 | D37: =D36 -> 2804.6154 | E37: =E36 -> 2756.4693 | F37: =F36 -> 2708.018 | G37: =G36 -> 3398.7346 | H37: =H36 -> 3339.0807 | I37: =I36 -> 3279.0541 | ... R37: =R36 -> 0
A39: TOTAL LIABILITIES | B39: =B33+B37 -> 1026 | C39: =C33+C37 -> 3122.4583 | D39: =D33+D37 -> 3108.6154 | E39: =E33+E37 -> 3095.4693 | F39: =F33+F37 -> 3084.018 | G39: =G33+G37 -> 3797.7346 | H39: =H33+H37 -> 3753.0807 | I39: =I33+I37 -> 3689.0541 | ... R39: =R33+R37 -> 1067.0653
A41: EQUITY
A42: Beginning Equity | B42: =Assumptions!B150 -> 747 | C42: =B45+Assumptions!B79 -> 2247 | D42: =C45 -> 2248.5305 | E42: =D45 -> 2252.0826 | F42: =E45 -> 2267.9223 | G42: =F45 -> 2297.4949 | H42: =G45 -> 2337.1051 | I42: =H45 -> 2383.4744 | J42: =I45 -> 2435.5051 | K42: =J45 -> 2484.5804 | ... R42: =Q45 -> 5206.6059
A43: Net Income | B43: 0 | C43: ='Income Statement'!B27 -> 1.6818888 | D43: ='Income Statement'!C27 -> 3.9034127 | E43: ='Income Statement'!D27 -> 17.406284 | F43: ='Income Statement'!E27 -> 32.497346 | G43: ='Income Statement'!F27 -> 43.527647 | H43: ='Income Statement'!G27 -> 50.955344 | I43: ='Income Statement'!H27 -> 57.17652 | J43: ='Income Statement'!I27 -> 53.928881 | ... N43: ='Income Statement'!M27 -> -14.602788 | O43: ='Income Statement'!O27 -> 524.42731 | P43: ='Income Statement'!P27 -> 978.49323 | Q43: ='Income Statement'!Q27 -> 1469.5411 | R43: ='Income Statement'!R27 -> 1970.9932
